latest: Pulling from airbyte/connector-acceptance-test
Digest: sha256:586ac71a07285ec74ae4c57245113fc8312357591d4778fbb52135109c1d0347
Status: Image is up to date for airbyte/connector-acceptance-test:latest
docker.io/airbyte/connector-acceptance-test:latest
[1mTest session starts (platform: linux, Python 3.9.11, pytest 6.2.5, pytest-sugar 0.9.6)[0m
rootdir: /test_input
plugins: timeout-1.4.2, hypothesis-6.54.6, requests-mock-1.9.3, cov-3.0.0, sugar-0.9.6, mock-3.6.1
[1mcollecting ... [0m
â€•â€•â€•â€•â€•â€•â€•â€•â€•â€•â€•â€•â€•â€•â€•â€•â€•â€•â€•â€•â€•â€•â€•â€• ERROR collecting test_core.py â€•â€•â€•â€•â€•â€•â€•â€•â€•â€•â€•â€•â€•â€•â€•â€•â€•â€•â€•â€•â€•â€•â€•â€•â€•
[1m[31m/usr/local/lib/python3.9/site-packages/pluggy/_hooks.py[0m:265: in __call__
    [94mreturn[39;49;00m [96mself[39;49;00m._hookexec([96mself[39;49;00m.name, [96mself[39;49;00m.get_hookimpls(), kwargs, firstresult)[90m[39;49;00m
[1m[31m/usr/local/lib/python3.9/site-packages/pluggy/_manager.py[0m:80: in _hookexec
    [94mreturn[39;49;00m [96mself[39;49;00m._inner_hookexec(hook_name, methods, kwargs, firstresult)[90m[39;49;00m
[1m[31m/usr/local/lib/python3.9/site-packages/_pytest/python.py[0m:249: in pytest_pycollect_makeitem
    res = [96mlist[39;49;00m(collector._genfunctions(name, obj))[90m[39;49;00m
[1m[31m/usr/local/lib/python3.9/site-packages/_pytest/python.py[0m:470: in _genfunctions
    [96mself[39;49;00m.ihook.pytest_generate_tests.call_extra(methods, [96mdict[39;49;00m(metafunc=metafunc))[90m[39;49;00m
[1m[31m/usr/local/lib/python3.9/site-packages/pluggy/_hooks.py[0m:292: in call_extra
    [94mreturn[39;49;00m [96mself[39;49;00m(**kwargs)[90m[39;49;00m
[1m[31m/usr/local/lib/python3.9/site-packages/pluggy/_hooks.py[0m:265: in __call__
    [94mreturn[39;49;00m [96mself[39;49;00m._hookexec([96mself[39;49;00m.name, [96mself[39;49;00m.get_hookimpls(), kwargs, firstresult)[90m[39;49;00m
[1m[31m/usr/local/lib/python3.9/site-packages/pluggy/_manager.py[0m:80: in _hookexec
    [94mreturn[39;49;00m [96mself[39;49;00m._inner_hookexec(hook_name, methods, kwargs, firstresult)[90m[39;49;00m
[1m[31mconnector_acceptance_test/plugin.py[0m:54: in pytest_generate_tests
    global_config = load_config(metafunc.config.getoption([33m"[39;49;00m[33m--acceptance-test-config[39;49;00m[33m"[39;49;00m))[90m[39;49;00m
[1m[31mconnector_acceptance_test/utils/common.py[0m:34: in load_config
    pytest.fail([33mf[39;49;00m[33m"[39;49;00m[33mconfig file [39;49;00m[33m{[39;49;00mpath.absolute()[33m}[39;49;00m[33m does not exist[39;49;00m[33m"[39;49;00m)[90m[39;49;00m
[1m[31mE   Failed: config file /test_input/acceptance-test-config.yml does not exist[0m

â€•â€•â€•â€•â€•â€•â€•â€•â€•â€•â€•â€•â€•â€•â€•â€•â€•â€•â€•â€•â€•â€•â€•â€• ERROR collecting test_core.py â€•â€•â€•â€•â€•â€•â€•â€•â€•â€•â€•â€•â€•â€•â€•â€•â€•â€•â€•â€•â€•â€•â€•â€•â€•
[1m[31m/usr/local/lib/python3.9/site-packages/pluggy/_hooks.py[0m:265: in __call__
    [94mreturn[39;49;00m [96mself[39;49;00m._hookexec([96mself[39;49;00m.name, [96mself[39;49;00m.get_hookimpls(), kwargs, firstresult)[90m[39;49;00m
[1m[31m/usr/local/lib/python3.9/site-packages/pluggy/_manager.py[0m:80: in _hookexec
    [94mreturn[39;49;00m [96mself[39;49;00m._inner_hookexec(hook_name, methods, kwargs, firstresult)[90m[39;49;00m
[1m[31m/usr/local/lib/python3.9/site-packages/_pytest/python.py[0m:249: in pytest_pycollect_makeitem
    res = [96mlist[39;49;00m(collector._genfunctions(name, obj))[90m[39;49;00m
[1m[31m/usr/local/lib/python3.9/site-packages/_pytest/python.py[0m:470: in _genfunctions
    [96mself[39;49;00m.ihook.pytest_generate_tests.call_extra(methods, [96mdict[39;49;00m(metafunc=metafunc))[90m[39;49;00m
[1m[31m/usr/local/lib/python3.9/site-packages/pluggy/_hooks.py[0m:292: in call_extra
    [94mreturn[39;49;00m [96mself[39;49;00m(**kwargs)[90m[39;49;00m
[1m[31m/usr/local/lib/python3.9/site-packages/pluggy/_hooks.py[0m:265: in __call__
    [94mreturn[39;49;00m [96mself[39;49;00m._hookexec([96mself[39;49;00m.name, [96mself[39;49;00m.get_hookimpls(), kwargs, firstresult)[90m[39;49;00m
[1m[31m/usr/local/lib/python3.9/site-packages/pluggy/_manager.py[0m:80: in _hookexec
    [94mreturn[39;49;00m [96mself[39;49;00m._inner_hookexec(hook_name, methods, kwargs, firstresult)[90m[39;49;00m
[1m[31mconnector_acceptance_test/plugin.py[0m:54: in pytest_generate_tests
    global_config = load_config(metafunc.config.getoption([33m"[39;49;00m[33m--acceptance-test-config[39;49;00m[33m"[39;49;00m))[90m[39;49;00m
[1m[31mconnector_acceptance_test/utils/common.py[0m:34: in load_config
    pytest.fail([33mf[39;49;00m[33m"[39;49;00m[33mconfig file [39;49;00m[33m{[39;49;00mpath.absolute()[33m}[39;49;00m[33m does not exist[39;49;00m[33m"[39;49;00m)[90m[39;49;00m
[1m[31mE   Failed: config file /test_input/acceptance-test-config.yml does not exist[0m

â€•â€•â€•â€•â€•â€•â€•â€•â€•â€•â€•â€•â€•â€•â€•â€•â€•â€•â€•â€•â€•â€•â€•â€• ERROR collecting test_core.py â€•â€•â€•â€•â€•â€•â€•â€•â€•â€•â€•â€•â€•â€•â€•â€•â€•â€•â€•â€•â€•â€•â€•â€•â€•
[1m[31m/usr/local/lib/python3.9/site-packages/pluggy/_hooks.py[0m:265: in __call__
    [94mreturn[39;49;00m [96mself[39;49;00m._hookexec([96mself[39;49;00m.name, [96mself[39;49;00m.get_hookimpls(), kwargs, firstresult)[90m[39;49;00m
[1m[31m/usr/local/lib/python3.9/site-packages/pluggy/_manager.py[0m:80: in _hookexec
    [94mreturn[39;49;00m [96mself[39;49;00m._inner_hookexec(hook_name, methods, kwargs, firstresult)[90m[39;49;00m
[1m[31m/usr/local/lib/python3.9/site-packages/_pytest/python.py[0m:249: in pytest_pycollect_makeitem
    res = [96mlist[39;49;00m(collector._genfunctions(name, obj))[90m[39;49;00m
[1m[31m/usr/local/lib/python3.9/site-packages/_pytest/python.py[0m:470: in _genfunctions
    [96mself[39;49;00m.ihook.pytest_generate_tests.call_extra(methods, [96mdict[39;49;00m(metafunc=metafunc))[90m[39;49;00m
[1m[31m/usr/local/lib/python3.9/site-packages/pluggy/_hooks.py[0m:292: in call_extra
    [94mreturn[39;49;00m [96mself[39;49;00m(**kwargs)[90m[39;49;00m
[1m[31m/usr/local/lib/python3.9/site-packages/pluggy/_hooks.py[0m:265: in __call__
    [94mreturn[39;49;00m [96mself[39;49;00m._hookexec([96mself[39;49;00m.name, [96mself[39;49;00m.get_hookimpls(), kwargs, firstresult)[90m[39;49;00m
[1m[31m/usr/local/lib/python3.9/site-packages/pluggy/_manager.py[0m:80: in _hookexec
    [94mreturn[39;49;00m [96mself[39;49;00m._inner_hookexec(hook_name, methods, kwargs, firstresult)[90m[39;49;00m
[1m[31mconnector_acceptance_test/plugin.py[0m:54: in pytest_generate_tests
    global_config = load_config(metafunc.config.getoption([33m"[39;49;00m[33m--acceptance-test-config[39;49;00m[33m"[39;49;00m))[90m[39;49;00m
[1m[31mconnector_acceptance_test/utils/common.py[0m:34: in load_config
    pytest.fail([33mf[39;49;00m[33m"[39;49;00m[33mconfig file [39;49;00m[33m{[39;49;00mpath.absolute()[33m}[39;49;00m[33m does not exist[39;49;00m[33m"[39;49;00m)[90m[39;49;00m
[1m[31mE   Failed: config file /test_input/acceptance-test-config.yml does not exist[0m

â€•â€•â€•â€•â€•â€•â€•â€•â€•â€•â€•â€•â€•â€•â€•â€•â€•â€•â€•â€•â€•â€•â€•â€• ERROR collecting test_core.py â€•â€•â€•â€•â€•â€•â€•â€•â€•â€•â€•â€•â€•â€•â€•â€•â€•â€•â€•â€•â€•â€•â€•â€•â€•
[1m[31m/usr/local/lib/python3.9/site-packages/pluggy/_hooks.py[0m:265: in __call__
    [94mreturn[39;49;00m [96mself[39;49;00m._hookexec([96mself[39;49;00m.name, [96mself[39;49;00m.get_hookimpls(), kwargs, firstresult)[90m[39;49;00m
[1m[31m/usr/local/lib/python3.9/site-packages/pluggy/_manager.py[0m:80: in _hookexec
    [94mreturn[39;49;00m [96mself[39;49;00m._inner_hookexec(hook_name, methods, kwargs, firstresult)[90m[39;49;00m
[1m[31m/usr/local/lib/python3.9/site-packages/_pytest/python.py[0m:249: in pytest_pycollect_makeitem
    res = [96mlist[39;49;00m(collector._genfunctions(name, obj))[90m[39;49;00m
[1m[31m/usr/local/lib/python3.9/site-packages/_pytest/python.py[0m:470: in _genfunctions
    [96mself[39;49;00m.ihook.pytest_generate_tests.call_extra(methods, [96mdict[39;49;00m(metafunc=metafunc))[90m[39;49;00m
[1m[31m/usr/local/lib/python3.9/site-packages/pluggy/_hooks.py[0m:292: in call_extra
    [94mreturn[39;49;00m [96mself[39;49;00m(**kwargs)[90m[39;49;00m
[1m[31m/usr/local/lib/python3.9/site-packages/pluggy/_hooks.py[0m:265: in __call__
    [94mreturn[39;49;00m [96mself[39;49;00m._hookexec([96mself[39;49;00m.name, [96mself[39;49;00m.get_hookimpls(), kwargs, firstresult)[90m[39;49;00m
[1m[31m/usr/local/lib/python3.9/site-packages/pluggy/_manager.py[0m:80: in _hookexec
    [94mreturn[39;49;00m [96mself[39;49;00m._inner_hookexec(hook_name, methods, kwargs, firstresult)[90m[39;49;00m
[1m[31mconnector_acceptance_test/plugin.py[0m:54: in pytest_generate_tests
    global_config = load_config(metafunc.config.getoption([33m"[39;49;00m[33m--acceptance-test-config[39;49;00m[33m"[39;49;00m))[90m[39;49;00m
[1m[31mconnector_acceptance_test/utils/common.py[0m:34: in load_config
    pytest.fail([33mf[39;49;00m[33m"[39;49;00m[33mconfig file [39;49;00m[33m{[39;49;00mpath.absolute()[33m}[39;49;00m[33m does not exist[39;49;00m[33m"[39;49;00m)[90m[39;49;00m
[1m[31mE   Failed: config file /test_input/acceptance-test-config.yml does not exist[0m

â€•â€•â€•â€•â€•â€•â€•â€•â€•â€•â€•â€•â€•â€•â€•â€•â€•â€•â€•â€• ERROR collecting test_full_refresh.py â€•â€•â€•â€•â€•â€•â€•â€•â€•â€•â€•â€•â€•â€•â€•â€•â€•â€•â€•â€•â€•
[1m[31m/usr/local/lib/python3.9/site-packages/pluggy/_hooks.py[0m:265: in __call__
    [94mreturn[39;49;00m [96mself[39;49;00m._hookexec([96mself[39;49;00m.name, [96mself[39;49;00m.get_hookimpls(), kwargs, firstresult)[90m[39;49;00m
[1m[31m/usr/local/lib/python3.9/site-packages/pluggy/_manager.py[0m:80: in _hookexec
    [94mreturn[39;49;00m [96mself[39;49;00m._inner_hookexec(hook_name, methods, kwargs, firstresult)[90m[39;49;00m
[1m[31m/usr/local/lib/python3.9/site-packages/_pytest/python.py[0m:249: in pytest_pycollect_makeitem
    res = [96mlist[39;49;00m(collector._genfunctions(name, obj))[90m[39;49;00m
[1m[31m/usr/local/lib/python3.9/site-packages/_pytest/python.py[0m:470: in _genfunctions
    [96mself[39;49;00m.ihook.pytest_generate_tests.call_extra(methods, [96mdict[39;49;00m(metafunc=metafunc))[90m[39;49;00m
[1m[31m/usr/local/lib/python3.9/site-packages/pluggy/_hooks.py[0m:292: in call_extra
    [94mreturn[39;49;00m [96mself[39;49;00m(**kwargs)[90m[39;49;00m
[1m[31m/usr/local/lib/python3.9/site-packages/pluggy/_hooks.py[0m:265: in __call__
    [94mreturn[39;49;00m [96mself[39;49;00m._hookexec([96mself[39;49;00m.name, [96mself[39;49;00m.get_hookimpls(), kwargs, firstresult)[90m[39;49;00m
[1m[31m/usr/local/lib/python3.9/site-packages/pluggy/_manager.py[0m:80: in _hookexec
    [94mreturn[39;49;00m [96mself[39;49;00m._inner_hookexec(hook_name, methods, kwargs, firstresult)[90m[39;49;00m
[1m[31mconnector_acceptance_test/plugin.py[0m:54: in pytest_generate_tests
    global_config = load_config(metafunc.config.getoption([33m"[39;49;00m[33m--acceptance-test-config[39;49;00m[33m"[39;49;00m))[90m[39;49;00m
[1m[31mconnector_acceptance_test/utils/common.py[0m:34: in load_config
    pytest.fail([33mf[39;49;00m[33m"[39;49;00m[33mconfig file [39;49;00m[33m{[39;49;00mpath.absolute()[33m}[39;49;00m[33m does not exist[39;49;00m[33m"[39;49;00m)[90m[39;49;00m
[1m[31mE   Failed: config file /test_input/acceptance-test-config.yml does not exist[0m

â€•â€•â€•â€•â€•â€•â€•â€•â€•â€•â€•â€•â€•â€•â€•â€•â€•â€•â€•â€•â€• ERROR collecting test_incremental.py â€•â€•â€•â€•â€•â€•â€•â€•â€•â€•â€•â€•â€•â€•â€•â€•â€•â€•â€•â€•â€•
[1m[31m/usr/local/lib/python3.9/site-packages/pluggy/_hooks.py[0m:265: in __call__
    [94mreturn[39;49;00m [96mself[39;49;00m._hookexec([96mself[39;49;00m.name, [96mself[39;49;00m.get_hookimpls(), kwargs, firstresult)[90m[39;49;00m
[1m[31m/usr/local/lib/python3.9/site-packages/pluggy/_manager.py[0m:80: in _hookexec
    [94mreturn[39;49;00m [96mself[39;49;00m._inner_hookexec(hook_name, methods, kwargs, firstresult)[90m[39;49;00m
[1m[31m/usr/local/lib/python3.9/site-packages/_pytest/python.py[0m:249: in pytest_pycollect_makeitem
    res = [96mlist[39;49;00m(collector._genfunctions(name, obj))[90m[39;49;00m
[1m[31m/usr/local/lib/python3.9/site-packages/_pytest/python.py[0m:470: in _genfunctions
    [96mself[39;49;00m.ihook.pytest_generate_tests.call_extra(methods, [96mdict[39;49;00m(metafunc=metafunc))[90m[39;49;00m
[1m[31m/usr/local/lib/python3.9/site-packages/pluggy/_hooks.py[0m:292: in call_extra
    [94mreturn[39;49;00m [96mself[39;49;00m(**kwargs)[90m[39;49;00m
[1m[31m/usr/local/lib/python3.9/site-packages/pluggy/_hooks.py[0m:265: in __call__
    [94mreturn[39;49;00m [96mself[39;49;00m._hookexec([96mself[39;49;00m.name, [96mself[39;49;00m.get_hookimpls(), kwargs, firstresult)[90m[39;49;00m
[1m[31m/usr/local/lib/python3.9/site-packages/pluggy/_manager.py[0m:80: in _hookexec
    [94mreturn[39;49;00m [96mself[39;49;00m._inner_hookexec(hook_name, methods, kwargs, firstresult)[90m[39;49;00m
[1m[31mconnector_acceptance_test/plugin.py[0m:54: in pytest_generate_tests
    global_config = load_config(metafunc.config.getoption([33m"[39;49;00m[33m--acceptance-test-config[39;49;00m[33m"[39;49;00m))[90m[39;49;00m
[1m[31mconnector_acceptance_test/utils/common.py[0m:34: in load_config
    pytest.fail([33mf[39;49;00m[33m"[39;49;00m[33mconfig file [39;49;00m[33m{[39;49;00mpath.absolute()[33m}[39;49;00m[33m does not exist[39;49;00m[33m"[39;49;00m)[90m[39;49;00m
[1m[31mE   Failed: config file /test_input/acceptance-test-config.yml does not exist[0m
INTERNALERROR> Traceback (most recent call last):
INTERNALERROR>   File "/usr/local/lib/python3.9/site-packages/_pytest/main.py", line 269, in wrap_session
INTERNALERROR>     session.exitstatus = doit(config, session) or 0
INTERNALERROR>   File "/usr/local/lib/python3.9/site-packages/_pytest/main.py", line 322, in _main
INTERNALERROR>     config.hook.pytest_collection(session=session)
INTERNALERROR>   File "/usr/local/lib/python3.9/site-packages/pluggy/_hooks.py", line 265, in __call__
INTERNALERROR>     return self._hookexec(self.name, self.get_hookimpls(), kwargs, firstresult)
INTERNALERROR>   File "/usr/local/lib/python3.9/site-packages/pluggy/_manager.py", line 80, in _hookexec
INTERNALERROR>     return self._inner_hookexec(hook_name, methods, kwargs, firstresult)
INTERNALERROR>   File "/usr/local/lib/python3.9/site-packages/pluggy/_callers.py", line 60, in _multicall
INTERNALERROR>     return outcome.get_result()
INTERNALERROR>   File "/usr/local/lib/python3.9/site-packages/pluggy/_result.py", line 60, in get_result
INTERNALERROR>     raise ex[1].with_traceback(ex[2])
INTERNALERROR>   File "/usr/local/lib/python3.9/site-packages/pluggy/_callers.py", line 39, in _multicall
INTERNALERROR>     res = hook_impl.function(*args)
INTERNALERROR>   File "/usr/local/lib/python3.9/site-packages/_pytest/main.py", line 333, in pytest_collection
INTERNALERROR>     session.perform_collect()
INTERNALERROR>   File "/usr/local/lib/python3.9/site-packages/_pytest/main.py", line 637, in perform_collect
INTERNALERROR>     hook.pytest_collection_modifyitems(
INTERNALERROR>   File "/usr/local/lib/python3.9/site-packages/pluggy/_hooks.py", line 265, in __call__
INTERNALERROR>     return self._hookexec(self.name, self.get_hookimpls(), kwargs, firstresult)
INTERNALERROR>   File "/usr/local/lib/python3.9/site-packages/pluggy/_manager.py", line 80, in _hookexec
INTERNALERROR>     return self._inner_hookexec(hook_name, methods, kwargs, firstresult)
INTERNALERROR>   File "/usr/local/lib/python3.9/site-packages/pluggy/_callers.py", line 60, in _multicall
INTERNALERROR>     return outcome.get_result()
INTERNALERROR>   File "/usr/local/lib/python3.9/site-packages/pluggy/_result.py", line 60, in get_result
INTERNALERROR>     raise ex[1].with_traceback(ex[2])
INTERNALERROR>   File "/usr/local/lib/python3.9/site-packages/pluggy/_callers.py", line 39, in _multicall
INTERNALERROR>     res = hook_impl.function(*args)
INTERNALERROR>   File "/airbyte/connector_acceptance_test/connector_acceptance_test/plugin.py", line 120, in pytest_collection_modifyitems
INTERNALERROR>     config = load_config(config.getoption("--acceptance-test-config"))
INTERNALERROR>   File "/airbyte/connector_acceptance_test/connector_acceptance_test/utils/common.py", line 34, in load_config
INTERNALERROR>     pytest.fail(f"config file {path.absolute()} does not exist")
INTERNALERROR>   File "/usr/local/lib/python3.9/site-packages/_pytest/outcomes.py", line 153, in fail
INTERNALERROR>     raise Failed(msg=msg, pytrace=pytrace)
INTERNALERROR> Failed: config file /test_input/acceptance-test-config.yml does not exist



Results (2.18s):
